{
  "source_file": "/mnt/chromeos/removable/USB Drive/review_assistant/outputs/chunks/050ac12f9b7f_195.json",
  "summary": "### Chunk unknown \u2014 unknown\n\n20 lines\nIndentationError: unexpected indent\n\u274c Helper script failed: /home/km_project/venvs/review_assistant_env/bin/python3 /mnt/chromeos/removable/USB Drive/review_assistant/python/file_summarizer.py --input-dir /mnt/chromeos/removable/USB Drive/review_assistant/outputs/chunks --output-dir /mnt/chromeos/removable/USB Drive/review_assistant/outputs/summaries\n\u2705  Latest chat file: /mnt/chromeos/removable/USB Drive/review_assistant/codebase/chat_sessions/Chat_with_CFO_20250521_125041.txt\n\ud83d\udd2a  Chunking chat file\u2026\n\u2713 390/390 chunks written to /mnt/chromeos/removable/USB Drive/review_assistant/outputs/chunks\n\ud83e\udde0  Summarising chunks\u2026\n  File \"/mnt/chromeos/removable/USB Drive/review_assistant/python/file_summarizer.py\", line 43\n    preview = \"\\n\".join(lines[:20])            # first 20 lines\nIndentationError: unexpected indent\nChatGPT said:\nThe error you're encountering:\n\nIndentationError: unexpected indent\nmeans that Python found an indentation that doesn't match the expected pattern \u2014 often caused by mixing tabs and spaces, or inconsistent levels of indentation.\n\n\ud83d\udd27 Fix It\nOpen your file_summarizer.py file and check line 43:\n\npreview = \"\\n\".join(lines[:20])            # first 20 lines\n\n\u2026"
}